<?xml version="1.0"?>
<robot name="armproject">

  <link name="base_link">
   <visual>
     <origin xyz="0 0 0.035" rpy="0 0 0" />
     <geometry>
       <cylinder radius="0.005" length="0.07"/>
     </geometry>
   </visual>
   <collision>
     <origin xyz="0 0 0.035" rpy="0 0 0"/>
     <geometry>
       <cylinder radius="0.005" length="0.07"/>
     </geometry>
   </collision>
  </link>


  <link name="link0">
   <visual>
     <origin xyz="0 -0.01 0" rpy="-1.5708 0 0" />
     <geometry>
       <cylinder radius="0.005" length="0.02"/>
     </geometry>
   </visual>
   <collision>
     <origin xyz="0 -0.01 0" rpy="-1.5708 0 0"/>
     <geometry>
       <cylinder radius="0.025" length="0.02"/>
     </geometry>
   </collision>
  </link>

  <link name="link1">
   <visual>
     <origin xyz="0 0 0.0475" rpy="0 0 0" />
     <geometry>
       <cylinder radius="0.005" length="0.095"/>
     </geometry>
   </visual>
   <collision>
     <origin xyz="0 0 0.0475" rpy="0 0 0"/>
     <geometry>
       <cylinder radius="0.025" length="0.095"/>
     </geometry>
   </collision>
  </link>

  <link name="link2">
   <visual>
     <origin xyz="0 0.0079 0" rpy="-1.5708 0 0" />
     <geometry>
       <cylinder radius="0.005" length="0.0158"/>
     </geometry>
   </visual>
   <collision>
     <origin xyz="0 0.0079 0" rpy="-1.5708 0 0"/>
     <geometry>
       <cylinder radius="0.015" length="0.0158"/>
     </geometry>
   </collision>
  </link>

  <link name="link3">
   <visual>
     <origin xyz="0.01 0 0" rpy="0 1.5708 -0.05258" />
     <geometry>
       <cylinder radius="0.005" length="0.02"/>
     </geometry>
   </visual>
   <collision>
     <origin xyz="0.015 0 0" rpy="0 1.5708 0"/>
     <geometry>
       <cylinder radius="0.015" length="0.03"/>
     </geometry>
   </collision>
  </link>

  <link name="link4">
   <visual>
     <origin xyz="0 0 -0.0475" rpy="0 0 0"/>
     <geometry>
       <cylinder radius="0.005" length="0.095"/>
     </geometry>
   </visual>
   <collision>
     <origin xyz="0 0 -0.0475" rpy="0 0 0"/>
     <geometry>
       <cylinder radius="0.025" length="0.095"/>
     </geometry>
   </collision>
  </link>

  <link name="link5">
   <visual>
     <origin xyz="-0.025 0 0" rpy="0 -1.5708 0"/>
     <geometry>
       <cylinder radius="0.005" length="0.05"/>
     </geometry>
   </visual>
   <collision>
     <origin xyz="-0.0255 0 0" rpy="0 -1.5708 0"/>
     <geometry>
       <cylinder radius="0.025" length="0.051"/>
     </geometry>
   </collision>
  </link>

  <link name="link6">
   <visual>
     <origin xyz="0 0 -0.03275" rpy="0 0 0"/>
     <geometry>
       <cylinder radius="0.005" length="0.0655"/>
     </geometry>
   </visual>
   <collision>
     <origin xyz="0 0 -0.03275" rpy="0 0 0"/>
     <geometry>
       <cylinder radius="0.01" length="0.0655"/>
     </geometry>
   </collision>
  </link>

  <link name="link7">
   <visual>
     <origin xyz="0.0175 0 0" rpy="0 1.5708 0"/>
     <geometry>
       <cylinder radius="0.005" length="0.035"/>
     </geometry>
   </visual>
   <collision>
     <origin xyz="0.0175 0 0" rpy="0 1.5708 0"/>
     <geometry>
       <cylinder radius="0.01" length="0.035"/>
     </geometry>
   </collision>
  </link>

  <link name="link8">
  </link>

  <joint name="rotate_robot" type="revolute">
    <parent link="base_link"/>
    <child link="link0"/>
    <axis xyz="0 0 1" />
    <origin rpy="0 0 0" xyz="0.0 0 0.07"/>
    <limit upper="1.570" lower ="-1.57" effort="1.0" velocity="1.0"/>
  </joint>

  <joint name="fixed_0" type="fixed">
    <parent link="link0"/>
    <child link="link1"/>
    <origin rpy="0 0 0" xyz="0.0 -0.02 0.0"/>
  </joint>

  <joint name="fixed_0a" type="fixed">
    <parent link="link1"/>
    <child link="link2"/>
    <origin rpy="0 0 0" xyz="0.0 0.0 0.095"/>
  </joint>

  <joint name="fixed_0b" type="fixed">
    <parent link="link2"/>
    <child link="link3"/>
    <origin rpy="0 0 0" xyz="0.0 0.0158 0.0"/>
  </joint>

  <joint name="up_down_movement" type="revolute">
    <parent link="link3"/>
    <child link="link4"/>
    <axis xyz="1 0 0" />
    <origin rpy="-1.5708 0 -0.05258" xyz="0.02 0.0 0.0"/>
    <limit upper="0.95" lower ="-0.35"  effort="1.0" velocity="1.0"/>
  </joint>

  <joint name="link_a" type="fixed">
    <parent link="link4"/>
    <child link="link5"/>
    <origin rpy="0.0 0 0" xyz="0.0 0 -0.095"/>
  </joint>

  <joint name="fine_movement" type="revolute">
    <parent link="link5"/>
    <child link="link6"/>
    <axis xyz="1 0 0" />
    <origin rpy="0 0 0" xyz="-0.05 0 0.0"/>
    <limit upper="1.15" lower ="-0.30"  effort="1.0" velocity="1.0"/>
  </joint>

  <joint name="link_b" type="fixed">
    <parent link="link6"/>
    <child link="link7"/>
    <origin rpy="0 0 0" xyz="0 0 -0.0655"/>
  </joint>

  <joint name="fixed_5" type="fixed">
    <parent link="link7"/>
    <child link="link8"/>
    <origin rpy="0 0 0" xyz="0.035 0 0.0"/>
  </joint>

</robot>

